<?xml version="1.0" encoding="UTF-8"?>
<testng-results skipped="0" failed="3" ignored="0" total="10" passed="7">
  <reporter-output>
  </reporter-output>
  <suite name="Suite" duration-ms="69" started-at="2017-12-07T07:25:16Z" finished-at="2017-12-07T07:25:16Z">
    <groups>
    </groups>
    <test name="Test" duration-ms="69" started-at="2017-12-07T07:25:16Z" finished-at="2017-12-07T07:25:16Z">
      <class name="com.test.TestPractice">
        <test-method status="PASS" signature="verifyTestCaseEight()[pri:0, instance:com.test.TestPractice@2669b199]" name="verifyTestCaseEight" duration-ms="13" started-at="2017-12-07T12:55:16Z" finished-at="2017-12-07T12:55:16Z">
          <reporter-output>
          </reporter-output>
        </test-method> <!-- verifyTestCaseEight -->
        <test-method status="PASS" signature="verifyTestCaseFive()[pri:0, instance:com.test.TestPractice@2669b199]" name="verifyTestCaseFive" duration-ms="1" started-at="2017-12-07T12:55:16Z" finished-at="2017-12-07T12:55:16Z">
          <reporter-output>
          </reporter-output>
        </test-method> <!-- verifyTestCaseFive -->
        <test-method status="FAIL" signature="verifyTestCaseFour()[pri:0, instance:com.test.TestPractice@2669b199]" name="verifyTestCaseFour" duration-ms="3" started-at="2017-12-07T12:55:16Z" finished-at="2017-12-07T12:55:16Z">
          <exception class="java.lang.AssertionError">
            <message>
              <![CDATA[Test Case Four Failed expected [true] but found [false]]]>
            </message>
            <full-stacktrace>
              <![CDATA[java.lang.AssertionError: Test Case Four Failed expected [true] but found [false]
	at org.testng.Assert.fail(Assert.java:93)
	at org.testng.Assert.failNotEquals(Assert.java:512)
	at org.testng.Assert.assertTrue(Assert.java:41)
	at com.test.TestPractice.verifyTestCaseFour(TestPractice.java:25)
	at sun.reflect.NativeMethodAccessorImpl.invoke0(Native Method)
	at sun.reflect.NativeMethodAccessorImpl.invoke(NativeMethodAccessorImpl.java:62)
	at sun.reflect.DelegatingMethodAccessorImpl.invoke(DelegatingMethodAccessorImpl.java:43)
	at java.lang.reflect.Method.invoke(Method.java:498)
	at org.testng.internal.MethodInvocationHelper.invokeMethod(MethodInvocationHelper.java:108)
	at org.testng.internal.Invoker.invokeMethod(Invoker.java:661)
	at org.testng.internal.Invoker.invokeTestMethod(Invoker.java:869)
	at org.testng.internal.Invoker.invokeTestMethods(Invoker.java:1193)
	at org.testng.internal.TestMethodWorker.invokeTestMethods(TestMethodWorker.java:126)
	at org.testng.internal.TestMethodWorker.run(TestMethodWorker.java:109)
	at org.testng.TestRunner.privateRun(TestRunner.java:744)
	at org.testng.TestRunner.run(TestRunner.java:602)
	at org.testng.SuiteRunner.runTest(SuiteRunner.java:380)
	at org.testng.SuiteRunner.runSequentially(SuiteRunner.java:375)
	at org.testng.SuiteRunner.privateRun(SuiteRunner.java:340)
	at org.testng.SuiteRunner.run(SuiteRunner.java:289)
	at org.testng.SuiteRunnerWorker.runSuite(SuiteRunnerWorker.java:52)
	at org.testng.SuiteRunnerWorker.run(SuiteRunnerWorker.java:86)
	at org.testng.TestNG.runSuitesSequentially(TestNG.java:1301)
	at org.testng.TestNG.runSuitesLocally(TestNG.java:1226)
	at org.testng.TestNG.runSuites(TestNG.java:1144)
	at org.testng.TestNG.run(TestNG.java:1115)
	at org.testng.remote.AbstractRemoteTestNG.run(AbstractRemoteTestNG.java:132)
	at org.testng.remote.RemoteTestNG.initAndRun(RemoteTestNG.java:236)
	at org.testng.remote.RemoteTestNG.main(RemoteTestNG.java:81)
]]>
            </full-stacktrace>
          </exception> <!-- java.lang.AssertionError -->
          <reporter-output>
          </reporter-output>
        </test-method> <!-- verifyTestCaseFour -->
        <test-method status="PASS" signature="verifyTestCaseNine()[pri:0, instance:com.test.TestPractice@2669b199]" name="verifyTestCaseNine" duration-ms="2" started-at="2017-12-07T12:55:16Z" finished-at="2017-12-07T12:55:16Z">
          <reporter-output>
          </reporter-output>
        </test-method> <!-- verifyTestCaseNine -->
        <test-method status="PASS" signature="verifyTestCaseOne()[pri:0, instance:com.test.TestPractice@2669b199]" name="verifyTestCaseOne" duration-ms="2" started-at="2017-12-07T12:55:16Z" finished-at="2017-12-07T12:55:16Z">
          <reporter-output>
          </reporter-output>
        </test-method> <!-- verifyTestCaseOne -->
        <test-method status="PASS" signature="verifyTestCaseSeven()[pri:0, instance:com.test.TestPractice@2669b199]" name="verifyTestCaseSeven" duration-ms="2" started-at="2017-12-07T12:55:16Z" finished-at="2017-12-07T12:55:16Z">
          <reporter-output>
          </reporter-output>
        </test-method> <!-- verifyTestCaseSeven -->
        <test-method status="PASS" signature="verifyTestCaseSix()[pri:0, instance:com.test.TestPractice@2669b199]" name="verifyTestCaseSix" duration-ms="2" started-at="2017-12-07T12:55:16Z" finished-at="2017-12-07T12:55:16Z">
          <reporter-output>
          </reporter-output>
        </test-method> <!-- verifyTestCaseSix -->
        <test-method status="FAIL" signature="verifyTestCaseTen()[pri:0, instance:com.test.TestPractice@2669b199]" name="verifyTestCaseTen" duration-ms="1" started-at="2017-12-07T12:55:16Z" finished-at="2017-12-07T12:55:16Z">
          <exception class="java.lang.AssertionError">
            <message>
              <![CDATA[Test Case Ten Failed expected [true] but found [false]]]>
            </message>
            <full-stacktrace>
              <![CDATA[java.lang.AssertionError: Test Case Ten Failed expected [true] but found [false]
	at org.testng.Assert.fail(Assert.java:93)
	at org.testng.Assert.failNotEquals(Assert.java:512)
	at org.testng.Assert.assertTrue(Assert.java:41)
	at com.test.TestPractice.verifyTestCaseTen(TestPractice.java:55)
	at sun.reflect.NativeMethodAccessorImpl.invoke0(Native Method)
	at sun.reflect.NativeMethodAccessorImpl.invoke(NativeMethodAccessorImpl.java:62)
	at sun.reflect.DelegatingMethodAccessorImpl.invoke(DelegatingMethodAccessorImpl.java:43)
	at java.lang.reflect.Method.invoke(Method.java:498)
	at org.testng.internal.MethodInvocationHelper.invokeMethod(MethodInvocationHelper.java:108)
	at org.testng.internal.Invoker.invokeMethod(Invoker.java:661)
	at org.testng.internal.Invoker.invokeTestMethod(Invoker.java:869)
	at org.testng.internal.Invoker.invokeTestMethods(Invoker.java:1193)
	at org.testng.internal.TestMethodWorker.invokeTestMethods(TestMethodWorker.java:126)
	at org.testng.internal.TestMethodWorker.run(TestMethodWorker.java:109)
	at org.testng.TestRunner.privateRun(TestRunner.java:744)
	at org.testng.TestRunner.run(TestRunner.java:602)
	at org.testng.SuiteRunner.runTest(SuiteRunner.java:380)
	at org.testng.SuiteRunner.runSequentially(SuiteRunner.java:375)
	at org.testng.SuiteRunner.privateRun(SuiteRunner.java:340)
	at org.testng.SuiteRunner.run(SuiteRunner.java:289)
	at org.testng.SuiteRunnerWorker.runSuite(SuiteRunnerWorker.java:52)
	at org.testng.SuiteRunnerWorker.run(SuiteRunnerWorker.java:86)
	at org.testng.TestNG.runSuitesSequentially(TestNG.java:1301)
	at org.testng.TestNG.runSuitesLocally(TestNG.java:1226)
	at org.testng.TestNG.runSuites(TestNG.java:1144)
	at org.testng.TestNG.run(TestNG.java:1115)
	at org.testng.remote.AbstractRemoteTestNG.run(AbstractRemoteTestNG.java:132)
	at org.testng.remote.RemoteTestNG.initAndRun(RemoteTestNG.java:236)
	at org.testng.remote.RemoteTestNG.main(RemoteTestNG.java:81)
]]>
            </full-stacktrace>
          </exception> <!-- java.lang.AssertionError -->
          <reporter-output>
          </reporter-output>
        </test-method> <!-- verifyTestCaseTen -->
        <test-method status="FAIL" signature="verifyTestCaseThree()[pri:0, instance:com.test.TestPractice@2669b199]" name="verifyTestCaseThree" duration-ms="2" started-at="2017-12-07T12:55:16Z" finished-at="2017-12-07T12:55:16Z">
          <exception class="java.lang.AssertionError">
            <message>
              <![CDATA[Test Case Three Failed expected [true] but found [false]]]>
            </message>
            <full-stacktrace>
              <![CDATA[java.lang.AssertionError: Test Case Three Failed expected [true] but found [false]
	at org.testng.Assert.fail(Assert.java:93)
	at org.testng.Assert.failNotEquals(Assert.java:512)
	at org.testng.Assert.assertTrue(Assert.java:41)
	at com.test.TestPractice.verifyTestCaseThree(TestPractice.java:20)
	at sun.reflect.NativeMethodAccessorImpl.invoke0(Native Method)
	at sun.reflect.NativeMethodAccessorImpl.invoke(NativeMethodAccessorImpl.java:62)
	at sun.reflect.DelegatingMethodAccessorImpl.invoke(DelegatingMethodAccessorImpl.java:43)
	at java.lang.reflect.Method.invoke(Method.java:498)
	at org.testng.internal.MethodInvocationHelper.invokeMethod(MethodInvocationHelper.java:108)
	at org.testng.internal.Invoker.invokeMethod(Invoker.java:661)
	at org.testng.internal.Invoker.invokeTestMethod(Invoker.java:869)
	at org.testng.internal.Invoker.invokeTestMethods(Invoker.java:1193)
	at org.testng.internal.TestMethodWorker.invokeTestMethods(TestMethodWorker.java:126)
	at org.testng.internal.TestMethodWorker.run(TestMethodWorker.java:109)
	at org.testng.TestRunner.privateRun(TestRunner.java:744)
	at org.testng.TestRunner.run(TestRunner.java:602)
	at org.testng.SuiteRunner.runTest(SuiteRunner.java:380)
	at org.testng.SuiteRunner.runSequentially(SuiteRunner.java:375)
	at org.testng.SuiteRunner.privateRun(SuiteRunner.java:340)
	at org.testng.SuiteRunner.run(SuiteRunner.java:289)
	at org.testng.SuiteRunnerWorker.runSuite(SuiteRunnerWorker.java:52)
	at org.testng.SuiteRunnerWorker.run(SuiteRunnerWorker.java:86)
	at org.testng.TestNG.runSuitesSequentially(TestNG.java:1301)
	at org.testng.TestNG.runSuitesLocally(TestNG.java:1226)
	at org.testng.TestNG.runSuites(TestNG.java:1144)
	at org.testng.TestNG.run(TestNG.java:1115)
	at org.testng.remote.AbstractRemoteTestNG.run(AbstractRemoteTestNG.java:132)
	at org.testng.remote.RemoteTestNG.initAndRun(RemoteTestNG.java:236)
	at org.testng.remote.RemoteTestNG.main(RemoteTestNG.java:81)
]]>
            </full-stacktrace>
          </exception> <!-- java.lang.AssertionError -->
          <reporter-output>
          </reporter-output>
        </test-method> <!-- verifyTestCaseThree -->
        <test-method status="PASS" signature="verifyTestCaseTwo()[pri:0, instance:com.test.TestPractice@2669b199]" name="verifyTestCaseTwo" duration-ms="1" started-at="2017-12-07T12:55:16Z" finished-at="2017-12-07T12:55:16Z">
          <reporter-output>
          </reporter-output>
        </test-method> <!-- verifyTestCaseTwo -->
      </class> <!-- com.test.TestPractice -->
    </test> <!-- Test -->
  </suite> <!-- Suite -->
</testng-results>
